Workbook

Sheet Config
A1: Clave | B1: Valor | C1: Descripción | L1: Años
A2: RUTA_RAIZ | C2: ID carpeta PAT | L2: 2026
A3: ID_PLANTILLA Nombre_Apellido_xxx | C3: ID plantilla alumno | L3: 2027
A4: ID_Seleccion_PAT | C4: Cupo por docente | L4: 2028
A5: ID_Directorio_Alumnos | C5: Directorio de Alumnos | L5: 2029
A6: SISTEMA_ACTIVO | C6: Habilitar sistema | L6: 2030
A7: VERSION | C7: Versión | L7: 2031
A8: BOTON_INSCRIPCION | C8: Habilita o no la inscripcion | L8: 2032
A9: ID_DirectorioBackUp | C9: Directorio de BackUp | L9: 2033
A10: Año actual | L10: 2034
A11: Email_ADMINISTRADOR | C11: Email principal | L11: 2035
A12: ID_LOGO | C12: Logo de la esceula | L12: 2036
A13: ID_Apps_Script
A14: ID_Egresados | C14: ID de la carpeta de Egresados
A15: ID_Bajas | C15: ID de la carpeta de Bajas

Sheet Respuesta del Formulario
A1: Timestamp | B1: Apellido del Estudiante | C1: Nombre del Estudiante | D1: DNI | E1: Nacionalidad | F1: Fecha Nacimiento | G1: Email Address | H1: Email ALU | I1: Distrito | J1: Municipio | K1: Calle | L1: CP | M1: Tutor1Nombre | N1: Tutor1Apellido | O1: Tutor1Telefono | P1: Tutor1Email | Q1: Tutor2Nombre | R1: Tutor2Apellido | S1: Tutor2Telefono | T1: Tutor2Email | U1: Ficha Salud | V1: Año | W1: División | X1: Turno | Y1: Especialidad | Z1: Nombre Docente | AA1: URL Archivo | AB1: URL Carpeta
A280: 46113.492 | B280: Mandrea | C280: Sofia Bianca | D280: 52642114 | E280: Argentina | F280: 41252 | G280: mandrea.sofia.et21.26@gmail.com | H280: SIN DATO | I280: caba | J280: Villa Urquiza | K280: Quesada 5090 Dpto A | L280: 1431 | M280: Brenda Soledad | N280: Raño | O280: 1164974671 | P280: brendarano@gmail.com | Q280: SIN DATO | R280: SIN DATO | S280: 1144798172 (Hermano) | T280: osvaldo2418@hotmail.com | U280: SIN DATO | V280: 1 | W280: 2 | X280: TD | Y280: CB | Z280: Muiño, Claudia | AA280: https://docs.google.com/spreadsheets/d/19PxvPfGsGu8F3B0iIsOJYTqvfHWQSPK_pHgkXrO397s/edit?usp=drivesdk | AB280: https://drive.google.com/drive/folders/1VtbC3ANLqCxXDw_BqR_SHYEELqpyy98u
A281: 46133.695 | B281: Marín | C281: Ana | D281: 95550606 | E281: Venezonala | F281: 19/10/2007 | G281: marin.ana.et21.22@gmail.com | H281: anam0606@alu.bue.edu.ar | I281: CABA | J281: Belgrano | K281: Cuba | L281: 1428 | M281: Romnay | N281: Granado | O281: 1166571467 | P281: romnaygranado@gmail.com | Q281: Martin | R281: Marín | S281: 1166571486 | T281: martinjmquintero@gmail.com | V281: 5 | W281: 1 | X281: TD | Y281: CSC | Z281: Mitingay, Dardo Antonio | AA281: https://docs.google.com/spreadsheets/d/1S9WBiX0Sv4CQV-mrOtML-ZcBTOwtBtbAj5vbkBcI390/edit?usp=drivesdk | AB281: https://drive.google.com/drive/folders/1VtbC3ANLqCxXDw_BqR_SHYEELqpyy98u
A282: 46128.714 | B282: Ibañez | C282: Marlene | D282: 51340216 | E282: ARGENTINA | F282: 19/10/2011 | G282: ibanez.marlene.et21.25@gmail.com | H282: @alu.bue.edu.ar | I282: V. LOPEZ | J282: V. LOPEZ | K282: V. LOPEZ | L282: 1636 | M282: MELINA | N282: IBAÑEZ | O282: 1533138630 | P282: melii.2009@outlook.com | V282: 2 | W282: 6 | X282: TD | Y282: CB | Z282: Larretape, Mariano | AA282: https://docs.google.com/spreadsheets/d/182yp3rXNO3nEiUWuJUToySK5BZnA_Y4Z-CpwGtChvlY/edit?usp=drivesdk | AB282: https://drive.google.com/drive/folders/1VtbC3ANLqCxXDw_BqR_SHYEELqpyy98u
A283: 46127.558 | B283: Marques | C283: Guadalupe | D283: 50985250 | E283: Argentina | F283: 24/02/2011 | G283: Marques.guadalupe.et21.24@gmail.com | H283: psarmiento20_3003@alu.bue.edu.ar | I283: CABA,Pcia de BsAs | J283: Vicente Lopez | K283: Agustin alvarez 4277 | L283: 1603 | M283: Yanina Rosana | N283: Dell ‘ aica | O283: 116288-9160 | P283: Yanina.dellaica@bue.edu.ar | U283: Normal | V283: 3 | W283: 1 | X283: TD | Y283: CB | Z283: Cuiñas,Carolina | AA283: https://docs.google.com/spreadsheets/d/1Zcje-KX2TuwgnEHPD2P-Vv1YVb6QdoziI7yRGQPyfB8/edit?usp=drivesdk | AB283: https://drive.google.com/drive/folders/1VtbC3ANLqCxXDw_BqR_SHYEELqpyy98u
A284: 46132.48 | B284: Martel | C284: Sandra | D284: 49596681 | E284: Argentina | F284: 40156 | G284: sandra.martel.et21.23@gmail.com | H284: sandra.martel.et21.23@gmail.com | I284: José León Suárez | J284: General San Martín. | K284: Andrés lamas 8869 | L284: B1655 | M284: Marita | N284: Fabián Pizarro | O284: 1128616640 | P284: fabianpizarromarita@gmail.com | U284: - | V284: 4 | W284: 1 | X284: TD | Y284: CSM | Z284: Lignini, Silvina Fernanda | AA284: https://docs.google.com/spreadsheets/d/15BP5pihWRoAvUgXVPZBwAr_EtnvVd_XPrQyBwhpUl9k/edit?usp=drivesdk | AB284: https://drive.google.com/drive/folders/1VtbC3ANLqCxXDw_BqR_SHYEELqpyy98u
A285: 46141.471 | B285: Martel Fabian | C285: Nadia | D285: 47938284 | E285: ARGENTINA | F285: 23/07/2007 | G285: MARTEL.NADIA.ET21.23@GMAIL.COM | H285: NADIAM284@ALU.BUE.EDU.AR | I285: CIUDAD DE BS AS | J285: SAN MARTIN | K285: ANDRES LAMAS 8869 | L285: 1650 | M285: MARITA | N285: FABIAN | O285: 1128616640 | P285: FABIANPIZARROMARITA@GMAIL.COM | U285: NADA | V285: 6 | W285: 1 | X285: TD | Y285: CSM | Z285: Rizzo, Tamara | AA285: https://docs.google.com/spreadsheets/d/1wNHux6gRQp6oyM5_dFNLS4VeNGokLWt-ZBLVUp7Rrvk/edit?usp=drivesdk | AB285: https://drive.google.com/drive/folders/1VtbC3ANLqCxXDw_BqR_SHYEELqpyy98u
A286: 46134.372 | B286: Martin | C286: Vito | D286: 49194880 | E286: Argentina | F286: 20/01/2009 | G286: martin.vito.et21.22@gmail.com | H286: @alu.bue.edu.ar | I286: CABA | J286: Saavedra | K286: Ramallo 2360 | L286: 1429 | M286: Cristian | N286: Martin | O286: 11 6954 3835 | P286: ventausado3102@gmail.com | V286: 5 | W286: 1 | X286: TD | Y286: CSC | Z286: Mitingay, Dardo Antonio | AA286: https://docs.google.com/spreadsheets/d/1qPC24VtnV2C-Dhct518KwqXvnqmV1oSq_IVOeA6Vt0w/edit?usp=drivesdk | AB286: https://drive.google.com/drive/folders/1VtbC3ANLqCxXDw_BqR_SHYEELqpyy98u
A287: 46112.455 | B287: Martinez | C287: Dante | D287: 52960327 | E287: Argentina | F287: 17/02/2013 | G287: Martinez.dante.et21.26@gmail.com | H287: @alu.bue.edu.ar | I287: CABA | J287: Villa Martelli | K287: General Las Heras 3686 | L287: 1603 | M287: Carolina | N287: Contreras | O287: 1168910434 | P287: ccc8caro@gmail.com | S287: 1124928250 | U287: No | V287: 1 | W287: 1 | X287: TD | Y287: CB | Z287: Balor, Verónica | AA287: https://docs.google.com/spreadsheets/d/1lPKgpKgkcnjhbfwUnZeGvZ2q0KHfF3m_KPUuYKTpvDU/edit?usp=drivesdk | AB287: https://drive.google.com/drive/folders/1VtbC3ANLqCxXDw_BqR_SHYEELqpyy98u
A288: 46136.613 | B288: Martinez | C288: Franco | D288: 51222019 | E288: Argentina | F288: 19/07/2011 | G288: martinez.franco.et21.25@gmail.com | H288: francomartinez@alu.edu.ar | I288: CABA | J288: Pcia.Bs. As. | K288: Las Heras 3686 | L288: 1602 | M288: Carolina | N288: Contreras | O288: 1168910434 | P288: ccc8caro@gmail.com | V288: 2 | W288: 6 | X288: TD | Y288: CB | Z288: Larretape, Mariano | AA288: https://docs.google.com/spreadsheets/d/1yFPSqF5FxurYxLK-hQWn6PUDDXnROxT6HcpBaFy-5X4/edit?usp=drivesdk | AB288: https://drive.google.com/drive/folders/1VtbC3ANLqCxXDw_BqR_SHYEELqpyy98u
A289: 46139.664 | B289: Martinez Costa | C289: Uma | D289: 52.718.220 | E289: Argentina | F289: 28/08/2012 | G289: martinezcosta.uma.et21.26@gmail.com | H289: - | I289: Buenos Aires | J289: Buenos Aires | K289: BUENOS AIRES | L289: 1430 | M289: , Alejandra Evelin | N289: COSTA | O289: 1132503087 (Madre) | P289: alejandraecosta@gmail.com | V289: 1 | W289: 7 | X289: TD | Y289: CB | Z289: Frías, Pablo Alberto | AA289: https://docs.google.com/spreadsheets/d/1fW-QgMHYMgroUc2aFXa32bBebR-Z-Zm2Qc5ox8p0PwU/edit?usp=drivesdk | AB289: https://drive.google.com/drive/folders/1VtbC3ANLqCxXDw_BqR_SHYEELqpyy98u
A290: 46141.809 | B290: Martinez nuñez | C290: Santiago | D290: 48183818 | E290: Argentina | F290: 39181 | G290: santiago.martinez.et21.21@gmail.com | H290: santiago.martinez.et21.21@gmail.com | I290: CABA | J290: CABA | K290: Neuquen | L290: 1405 | M290: Leticia | N290: Nuñez Bustos | O290: 11 2308 1655 | P290: nblety@gmail.com | V290: 6 | W290: 1 | X290: TN | Y290: CSC | Z290: Arosa, Mariangeles | AA290: https://docs.google.com/spreadsheets/d/1pbj5VSSwAXqtDFo-1wcxma7PlatVzio1i74FMO2xBqk/edit?usp=drivesdk | AB290: https://drive.google.com/drive/folders/1VtbC3ANLqCxXDw_BqR_SHYEELqpyy98u
A291: 46133.684 | B291: Mateos | C291: Julián | D291: 48861125 | E291: Argentina | F291: 39700 | G291: mateos.julian.et21.22@gmail.com | H291: mateosjulian499@gmail.com | I291: CABA | J291: CABA | K291: Dr Pedro Rivera 3478 | L291: 1430 | M291: Carlos Alberto | N291: Mateos | O291: 1140700088 | P291: arqcarlosmateos@gmail.com | Q291: Ana María | R291: Kettle | S291: 1151772057 | T291: anamaria.kettle@gmail.com | V291: 5 | W291: 1 | X291: TD | Y291: CSM | Z291: FABBIAN HERNÁN | AA291: https://docs.google.com/spreadsheets/d/1XxP6MUZHQnHKs188DQw31evbMmtMdNsDCO-RHGDhpDM/edit?usp=drivesdk | AB291: https://drive.google.com/drive/folders/1VtbC3ANLqCxXDw_BqR_SHYEELqpyy98u
A292: 46113.008 | B292: Maximov Lambre | C292: Ivan | D292: 52957876 | E292: Argentino | F292: 24/01/2013 | G292: maximov.ivan.et21.26@gmail.com | H292: @alu.bue.edu.ar | I292: CABA | J292: CABA | K292: CABA | L292: 1234 | M292: Georgina | N292: Lambre (Madre) | O292: 1155841003 | P292: georginalambre@gmail.com | V292: 1 | W292: 3 | X292: TD | Y292: CB | Z292: Aloma, Norma Mabel | AA292: https://docs.google.com/spreadsheets/d/1jiqPUKjcYxN__ISkl4hWaiXdM2k3eBcbU1SYPZKJk_Y/edit?usp=drivesdk | AB292: https://drive.google.com/drive/folders/1VtbC3ANLqCxXDw_BqR_SHYEELqpyy98u
A293: 46125.846 | B293: Mayorga | C293: Mateo | D293: 51268274 | E293: Argentino | F293: 15/07/2011 | G293: mayorga.mateo.et21.25@gmail.com | H293: aliu@com | I293: CABA | J293: Bs As (Vte Lopez) | K293: NO | L293: NO | M293: Nadina | N293: Forbes | O293: 1559479059 (Madre) | P293: mayo7@hotmail.com | S293: 1564576754 (Padre) | U293: Corroborar mail si es de mamá o papá | V293: 2 | W293: 2 | X293: TD | Y293: CB | Z293: García Osorio, Patricia | AA293: https://docs.google.com/spreadsheets/d/1RSzADnKOJwF_fOi20iQHn1JQAtCcpmdSV5b-Re1Thpk/edit?usp=drivesdk | AB293: https://drive.google.com/drive/folders/1VtbC3ANLqCxXDw_BqR_SHYEELqpyy98u
A294: 46135.446 | B294: Medela | C294: Demian | D294: 48639931 | E294: Argentina | F294: 23/05/2008 | G294: demian.medela.et21.21@gmail.com | H294: @alu.bue.edu.ar | I294: Provincia de Buenos Aires | J294: Vicente Lopez | K294: Lavalle 1494 | L294: 1638 | M294: Nadia | N294: Herrera | O294: =#error! -> #NAME? | P294: nadixher@gmail.com | V294: 6 | W294: 1 | X294: TD | Y294: CSC | Z294: Miranda, Gabriel | AA294: https://docs.google.com/spreadsheets/d/1GchOe5ZDJOYV-FjQvMjZ9O58ErS3sIPM79bdWESJLd0/edit?usp=drivesdk | AB294: https://drive.google.com/drive/folders/1VtbC3ANLqCxXDw_BqR_SHYEELqpyy98u
A295: 46128.451 | B295: Medina | C295: Enzo Gabriel | D295: 52.392.183 | E295: Argentino | F295: 24/04/2012 | G295: medina.enzo.et21.25@gmail.com | H295: ALU@G | I295: Bs As (Avellaneda) | J295: CABA | K295: NO | L295: NO | M295: Lucia | N295: Martínez Monzon | O295: 1161550385 (Madre) | P295: luciamartinezmm2010@gmail.com | S295: 1544770066 (Hermano) | V295: 2 | W295: 2 | X295: TD | Y295: CB | Z295: García Osorio, Patricia | AA295: https://docs.google.com/spreadsheets/d/1Ott0wQ9Tx-I_NXsA1bOB524S3AGJDI79aal9ZUtXKEg/edit?usp=drivesdk | AB295: https://drive.google.com/drive/folders/1VtbC3ANLqCxXDw_BqR_SHYEELqpyy98u
A296: 46140.402 | B296: Medio | C296: Mia Jazmin | D296: 50436047 | E296: Argentina | F296: 17/07/10 | G296: mia.medio.et21.24@gmail.com | H296: @alu.bue.edu.ar | I296: CABA | J296: Saavedra | K296: Holmberg 3709 | L296: 1430 | M296: Maria de los Angeles | N296: Chianelli | O296: 1168542306 | P296: mari.medi@hotmail.com | V296: 3 | W296: 1 | X296: TD | Y296: CB | Z296: Marmisolle, Pamela | AA296: https://docs.google.com/spreadsheets/d/1huC_MgOf8j1WxV5IJZG-BeYOt3cqiNV2HRIG6b8iTMQ/edit?usp=drivesdk | AB296: https://drive.google.com/drive/folders/1VtbC3ANLqCxXDw_BqR_SHYEELqpyy98u
A297: 46133.603 | B297: Medovoy | C297: Juanse | D297: 50298171 | E297: Argentino | F297: 14/08/10 | G297: medovoy.juanse.et21.24@gmail.com | H297: juanm8171@alu.bue.edu.ar | I297: Buenps Aires | J297: Avellaneda | K297: Solier 4480 | L297: 4480 | M297: Carina | N297: Barrios | O297: 11 63045647 | P297: caribariios1@hotgmail.com | Q297: Mariano | R297: Rabinovich | S297: 11 44203556 | T297: marmaruno@hotmail.com | V297: 3 | W297: 3 | X297: TD | Y297: CB | Z297: Coronel, Paola | AA297: https://docs.google.com/spreadsheets/d/1eTtePbXk7Jv4L-QYt5vF1LacRk-74w9iNlUkU224uyc/edit?usp=drivesdk | AB297: https://drive.google.com/drive/folders/1VtbC3ANLqCxXDw_BqR_SHYEELqpyy98u
A298: 46140.452 | B298: Meijide | C298: Federico | D298: 51265432 | E298: argentina | F298: 16/6/2011 | G298: meijide.federico.et21.24@gmail.com | H298: federicom432@alu.bue.edu.ar | I298: CABA | J298: villa urquiza | K298: burela 3547 | L298: 1431 | M298: adriana | N298: vanin | O298: 11 5454 5072 | P298: adrianamvanin@gmail.com | Q298: fernando | R298: meijide | S298: 11 5765 1929 | T298: fernandomei@yahoo.com.ar | U298: nada que agregar | V298: 3 | W298: 3 | X298: TD | Y298: CB | Z298: Carnero, Silvia | AA298: https://docs.google.com/spreadsheets/d/1RkAiQwijw4CMoxCWkLLUnGQwOCGa75RliqxWpZYwM5c/edit?usp=drivesdk | AB298: https://drive.google.com/drive/folders/1VtbC3ANLqCxXDw_BqR_SHYEELqpyy98u
A299: 46133.677 | B299: Meijide García | C299: Nicolás | D299: 49434195 | E299: Argentino | F299: 13/5/2009 | G299: meijide.nicolas.et21.22@gmail.com | H299: NicolasM195@alu.bue.edu.ar | I299: CABA | J299: Villa Urquiza | K299: Burela 3547 | L299: 1431 | M299: Adriana | N299: Vanin | O299: =#error! -> #NAME? | P299: adrianamvanin@gmail.com | Q299: Fernando | R299: Meijide García | S299: =#error! -> #NAME? | T299: fernandomei@yahoo.com.ar | V299: 5 | W299: 1 | X299: TD | Y299: CSC | Z299: Rodriguez, Leopoldo | AA299: https://docs.google.com/spreadsheets/d/1wrUF9DSTGIjbnck7VgcgxymnZzjjIMlgznMrAP-FzEw/edit?usp=drivesdk | AB299: https://drive.google.com/drive/folders/1VtbC3ANLqCxXDw_BqR_SHYEELqpyy98u
A300: 46113.479 | B300: Miceli | C300: Benicio Jeronimo | D300: 52772771 | E300: SIN DATOS | F300: 13/05/2012 | G300: miceli.benicio.et21.25@gmail.com | H300: beniciom2771@alu.bue.edu.ar | I300: SIN DATOS | J300: SIN DATOS | K300: SIN DATOS | L300: SIN DATOS | M300: Maria Eva | N300: Anitua | O300: SIN DATOS | P300: SIN DATOS | V300: 2 | W300: 1 | X300: TD | Y300: CB | Z300: Acosta Eduardo | AA300: https://docs.google.com/spreadsheets/d/11-oDXS_a5r43wB7Hz3shISL713b1YJxudrqgBwYfcyM/edit?usp=drivesdk | AB300: https://drive.google.com/drive/folders/1VtbC3ANLqCxXDw_BqR_SHYEELqpyy98u
A301: 46126.694 | B301: Miculan (Bruzzo) | C301: Ian | D301: 52162966 | E301: ARGNEITNO | F301: 41093 | G301: bruzzo.ian.et21.26@gmail.com | H301: bruzzo.ian.et21.26@gmail.com | I301: BS AS | J301: VILLA MAIPU | K301: FRENCH 1435 | L301: A | M301: DANIELA ESTER | N301: BRUZZO | O301: 1564819146 | P301: A | V301: 2 | W301: 4 | X301: TD | Y301: CB | Z301: D´Alessandro, Andreina | AA301: https://docs.google.com/spreadsheets/d/1mp4IsyqsEVigw4_deuKMyuY86vdIq23HP-J2H8ZwKuY/edit?usp=drivesdk | AB301: https://drive.google.com/drive/folders/1VtbC3ANLqCxXDw_BqR_SHYEELqpyy98u
A302: 46128.457 | B302: Migliaro | C302: Felipe | D302: 50701523 | E302: Argentina | F302: 40369 | G302: migliaro.felipe.et21.24@gmail.com | H302: felipem523@alu.bue.edu.ar | I302: Pcia de BsAs | J302: Florida | K302: Melo 2610 | L302: 1602 | M302: Pablo | N302: Migliaro | O302: 11 6832-7955 | P302: pmigliaro76@gmail.com | U302: No | V302: 3 | W302: 3 | X302: TD | Y302: CB | Z302: Carnero, Silvia | AA302: https://docs.google.com/spreadsheets/d/1x6miuEUft3JgKBjnaTfzUDbOTJMGIPcQO2UOMU9VBnE/edit?usp=drivesdk | AB302: https://drive.google.com/drive/folders/1VtbC3ANLqCxXDw_BqR_SHYEELqpyy98u
A303: 46128.471 | B303: Moauro | C303: Benjamin | D303: 50906804 | E303: argentino | F303: 26/01/2011 | G303: moauro.benja.et21.24@gmail.com | H303: moauro.benja.et21.24@gmail.com | I303: CABA | J303: belgrano r | K303: monroe 3226 | L303: 1428 | M303: carola | N303: bolla agrelo | O303: 1140897128 | P303: cbabochi@yahoo.com | V303: 3 | W303: 3 | X303: TD | Y303: CB | Z303: Carnero, Silvia | AA303: https://docs.google.com/spreadsheets/d/119l5BK7Omy96HaMZtOXBZk9vGxGoXFCkRAWeKLOotRA/edit?usp=drivesdk | AB303: https://drive.google.com/drive/folders/1VtbC3ANLqCxXDw_BqR_SHYEELqpyy98u
A304: 46135.451 | B304: Moauro | C304: Santino | D304: 49092416 | E304: argentino | F304: 31/10/2008 | G304: moauro.santino.et21.22@gmail.com | H304: @alu.bue.ar | I304: CABA, buenos aires | J304: Belgrano | K304: av monroe 3226 | L304: 1428 | M304: carola | N304: bolla agrelo | O304: =#error! -> #NAME? | P304: cbabochi@gmail.com | V304: 5 | W304: 1 | X304: TD | Y304: CSC | Z304: Rodriguez, Leopoldo | AA304: https://docs.google.com/spreadsheets/d/1cJ5ZimMP0s8EY0p6HWOTcrBNAfCjmcfsGia7HzHhM7M/edit?usp=drivesdk | AB304: https://drive.google.com/drive/folders/1VtbC3ANLqCxXDw_BqR_SHYEELqpyy98u
A305: 46132.821 | B305: Molina | C305: Luis Antonio | D305: 28992763 | E305: Argentino | F305: 23/08/1981 | G305: molina.luis.et21.26@gmail.com | H305: molinalucho1981@gmail.com | I305: caba | J305: caba | K305: romulo naon 3553 | L305: 1430 | M305: Luis | N305: Molina | O305: 1130189621 | P305: molinalucho1981@gmail.com | V305: 2 | W305: 5 | X305: TN | Y305: CB | Z305: Spuches, Marina | AA305: https://docs.google.com/spreadsheets/d/1OFsp4Ea1Oaxxji-NC2uzqZFBZyb_KgcXGhQCHm4N-Y8/edit?usp=drivesdk | AB305: https://drive.google.com/drive/folders/1VtbC3ANLqCxXDw_BqR_SHYEELqpyy98u
A306: 46113.457 | B306: Molina | C306: Santino Tahiel | D306: 53245973 | E306: SIN DATO | F306: 41311 | G306: molina.santino.et21.26@gmail.com | H306: SIN DATO | I306: CABA | J306: SIN DATO | K306: SIN DATO | L306: SIN DATO | M306: SIN DATO | N306: SIN DATO | O306: 1157605706 (Madre) | P306: claudiasantino123@gmail.com | Q306: SIN DATO | R306: SIN DATO | S306: 1140902346 (Padre) | T306: SIN DATO | U306: SIN DATO | V306: 1 | W306: 2 | X306: TD | Y306: CB | Z306: Acosta Eduardo | AA306: https://docs.google.com/spreadsheets/d/1XH9hYetTGR07ivrJXYGBgC45lN_K9aVqQf2g49lk3jY/edit?usp=drivesdk | AB306: https://drive.google.com/drive/folders/1VtbC3ANLqCxXDw_BqR_SHYEELqpyy98u
A307: 46120.495 | B307: Molina | C307: Tomás | D307: 52168111 | E307: Argentina | F307: 13/05/12 | G307: molina.tomas.et21.25@gmail.com | H307: molina.tomas.et21.25@gmail.com | I307: Provincia de BS. As. | J307: Vicente López | K307: Corroborar con alumno | L307: Corroborar con alumno | M307: María Florencia | N307: Cruz | O307: 1125351131 | P307: florencia76@hotmail.com | Q307: Martin | R307: Molina | S307: 1127371245 | T307: martinhmolina@hotmail.com | V307: 2 | W307: 6 | X307: TD | Y307: CB | Z307: Prats, Alejandro | AA307: https://docs.google.com/spreadsheets/d/1TAzXdbqax74l9_C8JtUTMr1fOpDBWogiZpMOrOHtciw/edit?usp=drivesdk | AB307: https://drive.google.com/drive/folders/1VtbC3ANLqCxXDw_BqR_SHYEELqpyy98u
A308: 46135.424 | B308: Montenegro | C308: Thiago | D308: 49434522 | E308: Argentina | F308: 39936 | G308: thiago.montenegro.et21.22@gmail.com | H308: thiagom522@alu.bue.edu.ar | I308: CABA | J308: Villa Urquiza | K308: Holmberg 3435 | L308: 1430 | M308: Gustavo | N308: Montenegro | O308: =#error! -> #NAME? | P308: montenegro.gustavo@hotmail.com | Q308: Vanina | R308: Rivera | S308: =#error! -> #NAME? | T308: rivera_vanina@hotmail.com | V308: 5 | W308: 1 | X308: TD | Y308: CSC | Z308: Rodriguez, Leopoldo | AA308: https://docs.google.com/spreadsheets/d/1B9xeOaFvKIpbYMrCvdFDveMKqqjS2DmO3r23wmX4ulQ/edit?usp=drivesdk | AB308: https://drive.google.com/drive/folders/1VtbC3ANLqCxXDw_BqR_SHYEELqpyy98u
A309: 46113.525 | B309: Montenegro Villagran | C309: Tomas Agustin | D309: 52166202 | E309: SIN DATOS | F309: 19/02/2012 | G309: montenegro.tomas.et21.25@gmail.com | H309: tomasm202@alu.bue.edu.ar | I309: SIN DATOS | J309: SIN DATOS | K309: SIN DATOS | L309: SIN DATOS | M309: Maria Eva | N309: Anitua | O309: SIN DATOS | P309: SIN DATOS | V309: 2 | W309: 1 | X309: TD | Y309: CB | Z309: Acosta Eduardo | AA309: https://docs.google.com/spreadsheets/d/1Lgo7A3ytcSl-XDy8EtaLjestmK2MUx5RbhQzHg6xR7M/edit?usp=drivesdk | AB309: https://drive.google.com/drive/folders/1VtbC3ANLqCxXDw_BqR_SHYEELqpyy98u
A310: 46113.767 | B310: Montes Barthel | C310: Emma | D310: 52142509 | E310: Argentina | F310: 41062 | G310: montes.emma.et21.25@gmail.com | H310: emmam509@alu.bue.edu.ar | I310: CABA | J310: CABA | K310: Roque Pérez 4385 | L310: 1430 | M310: Paula | N310: Carbajales | O310: SIN DATOS | P310: SIN DATOS | V310: 2 | W310: 1 | X310: TD | Y310: CB | Z310: Carbajales, Paula | AA310: https://docs.google.com/spreadsheets/d/13n_q08Z6OAcMtTTUQLS5S8_hvy-p4-mYK9iFhcOg4jI/edit?usp=drivesdk | AB310: https://drive.google.com/drive/folders/1VtbC3ANLqCxXDw_BqR_SHYEELqpyy98u
A311: 46132.458 | B311: Montes Barthel | C311: Julián | D311: 50257564 | E311: Argentina | F311: 20/4/26 | G311: julian.momtes.et21.23@gmail.com | H311: julianmontbarth@gmail.com | I311: CABA | J311: CGP12, Saavedra | K311: Roque Pérez 4385 | L311: 1430 | M311: Mario Omar | N311: Montes | O311: =#error! -> #NAME? | P311: montesmarioomar@gmail.com | Q311: Carla Romina | R311: Romina | S311: =#error! -> #NAME? | T311: crbarthel2@gmail.com | U311: - | V311: 4 | W311: 1 | X311: TD | Y311: CSM | Z311: Rondo Condori, Alejandro | AA311: https://docs.google.com/spreadsheets/d/1CCTVSLoo0dQJjWiUtcmTT3MVCxAcWuoDLlm2SNjR6Cs/edit?usp=drivesdk | AB311: https://drive.google.com/drive/folders/1VtbC3ANLqCxXDw_BqR_SHYEELqpyy98u
A312: 46119.69 | B312: Morales | C312: Eliseo Emanuel | D312: 52924767 | E312: Argentina | F312: 41396 | G312: morales.eliseo.et21.26@gmail.com | H312: alu.com.ar | I312: AMBA | J312: Tres de febrero | K312: Tres de febrero | L312: 1430 | M312: Yesica Natalia | N312: Loyola | O312: 1132655156 | P312: natyloyola0906@gmail.com | V312: 1 | W312: 4 | X312: TD | Y312: CB | Z312: González Novarin, Johanna | AA312: https://docs.google.com/spreadsheets/d/1o9RhcQFydAAZsQffbIxgdXOfMTdho_SFBmrLCBLbp4M/edit?usp=drivesdk | AB312: https://drive.google.com/drive/folders/1VtbC3ANLqCxXDw_BqR_SHYEELqpyy98u
A313: 46133.69 | B313: Morales Arrieta | C313: Lucas Benjamin | D313: 49121655 | E313: Argentina | F313: 39720 | G313: arrieta.lucas.et21.26@gmail.com | H313: lucas.arrietaet36@gmail.com | I313: CABA | J313: CABA | K313: Joaquín v Gonzáles | L313: 1419 | M313: Laura | N313: Arrieta | O313: 1539477967 | P313: lau.arrieta37@gmail.com | V313: 5 | W313: 1 | X313: TD | Y313: CSM | Z313: Torres, Carlos Alberto | AA313: https://docs.google.com/spreadsheets/d/15nvRm8SN0QXHNVbvydKe1MMzMqkjiNQ51eJHmHwRofk/edit?usp=drivesdk | AB313: https://drive.google.com/drive/folders/1oVZYT1yPNZnXLNdlHXbF_6MVref3-L-C
A314: 46113.904 | B314: Morel Landero | C314: Agustin | D314: 52761367 | E314: ARGENTINO | F314: 41223 | G314: agustin.morel.et21.26@gmail.com | H314: Agustinm367@alu.bue.edu.ar | I314: CABA | J314: Serrano | K314: Serrano 439 | L314: 1414 | M314: María | N314: Landeo | O314: 1163367578 | P314: Mary_nery26@hotmail.com | Q314: Desiderio | R314: Morel | S314: 11 5583 6127 | T314: Desideriomorel123@gmail.com | U314: iPod acustico | V314: 1 | W314: 1 | X314: TD | Y314: CB | Z314: Coronel, Paola | AA314: https://docs.google.com/spreadsheets/d/1DHXE418ezPiY4OpwKRVA_o3x8KP3Xq6vzYbFFU9NqHg/edit?usp=drivesdk | AB314: https://drive.google.com/drive/folders/1VtbC3ANLqCxXDw_BqR_SHYEELqpyy98u
A315: 46132.673 | B315: Muñoz | C315: Santino Martin | D315: 52193112 | E315: argentina | F315: 41154 | G315: matias.munoz.et21.25@gmail.com | H315: NN | I315: CABA | J315: CABA | K315: NN | L315: NN | M315: Verónica | N315: Balor | O315: 1133702709 | P315: veronicaa.balor@bue.edu.ar | V315: 2 | W315: 2 | X315: TD | Y315: CB | Z315: Balor, Verónica | AA315: https://docs.google.com/spreadsheets/d/1W2muwJnu5kh01ooEdoJlpJgZaHZQQcmWPgznCNBhG9g/edit?usp=drivesdk | AB315: https://drive.google.com/drive/folders/1VtbC3ANLqCxXDw_BqR_SHYEELqpyy98u
A316: 46113.464 | B316: Naftilsan Sobrino | C316: Teo | D316: 53088780 | E316: Argentina | F316: 41458 | G316: nsobrino.teo.et21.26@gmail.com | H316: SIN DATO | I316: Buenos Aires, Caba | J316: V.pueyrredon | K316: Bazurco 3105 dto C | L316: 1419 | M316: Marina Ivana | N316: Sobrino | O316: 1136479247 | P316: marinasobrino1@gmail.com | Q316: Gustavo Daniel | R316: Naftilsan | S316: =#error! -> #NAME? | T316: gustavoalepersonal@gmail.com | U316: SIN DATO | V316: 1 | W316: 2 | X316: TD | Y316: CB | Z316: Acosta Eduardo | AA316: https://docs.google.com/spreadsheets/d/1_lKnNM6675jXTqnwO-xalNym3PC-gE_s3hTW4RofBzc/edit?usp=drivesdk | AB316: https://drive.google.com/drive/folders/1j9L8oBZXmaOQ0PzTDKoEtrX_qLU0c-GO
A317: 46129.399 | B317: Neumann | C317: Esteban | D317: 49553084 | E317: Argentina | F317: 14/08/2010 | G317: esteban.neumann.et21.24@gmail.com | H317: @alu.bue.edu.ar | I317: CABA | J317: CABA, Coghlan | K317: Melian2738 | L317: 1430 | M317: Betina | N317: Ragni | O317: 11 6808-8304 | P317: betinaragni@yahoo.com.ar | Q317: Adrian | R317: Neumann | S317: 11 3030-5376 | T317: raneumann02@yahoo.com.ar | U317: Brackets | V317: 3 | W317: 3 | X317: TD | Y317: CB | Z317: Rodriguez, Leopoldo | AA317: https://docs.google.com/spreadsheets/d/1f5opm4E-vL9iaQuDM8PkKgFWCCsSFr6Bdb0Y1Cvm37U/edit?usp=drivesdk | AB317: https://drive.google.com/drive/folders/1j9L8oBZXmaOQ0PzTDKoEtrX_qLU0c-GO
A318: 46139.674 | B318: Noel | C318: Lisandro | D318: 53237214 | E318: argentina | F318: 22/4/2013 | G318: noel.lisandro.et21.26@gmail.com | H318: - | I318: caba | J318: caba | K318: caba | L318: 1430 | M318: Gabriela | N318: arrato | O318: 1150081166 | P318: gabriela.aratto@gmail.com | V318: 1 | W318: 7 | X318: TD | Y318: CB | Z318: Frías, Pablo Alberto | AA318: https://docs.google.com/spreadsheets/d/1kPwxOdwYH6R5xb5fl40Awvh87iVuA1pg4194idzq3wM/edit?usp=drivesdk | AB318: https://drive.google.com/drive/folders/1j9L8oBZXmaOQ0PzTDKoEtrX_qLU0c-GO
...

Sheet Docentes
A1: Apellido y Nombre | B1: Email | C1: DNI | D1: Situación | E1: Ciclos | F1: Turno | G1: Horas | H1: Horas sin Alumnos | I1: Maximo teórico | J1: Máx Alumnos | K1: Alumnos asignados | L1: Vacantes Disponibles | N1: Cantidad de alumnos diurno | P1: Cantidad de alumnos nocturno
N2: Teórico | O2: =SUMIF(F2:F91,"TD",I2:I91) -> 0 | P2: Teórico | Q2: =SUMIF(F2:F91,"Tn",I2:I91) -> 0
N3: Real | O3: =SUMIF(F2:F91,"TD",J2:J91) -> 0 | P3: Real | Q3: =SUMIF(F2:F91,"Tn",J2:J91) -> 0

Sheet Estadisticas
A1: Turno | B1: PAT | E1: No-PAT | F1: Cantidad de Alumnos | I1: Cupo máx. de alumnos PAT | L1: % de ocupacion
B2: Esp. | C2: Parcial | D2: Total | E2: Total | F2: Esp. | G2: Parcial | H2: Total | I2: Esp. | J2: Parcial | K2: Total | L2: Esp. | M2: Parcial | N2: Total
A3: Diurno | B3: CB | C3: =COUNTIFS(Docentes!F:F,"TD",Docentes!E:E,"CB",Docentes!J:J,">0") -> 0 | D3: =COUNTIFS(Docentes!F:F,"TD",Docentes!J:J,">0") -> 0 | E3: =COUNTIFS(Docentes!F:F,"TD",Docentes!J:J,"=0") -> 0 | F3: CB | G3: =COUNTIFS('Respuesta del Formulario'!X:X,"TD",'Respuesta del Formulario'!Y:Y,"CB") -> 144 | H3: =COUNTIFS('Respuesta del Formulario'!X:X,"TD") -> 199 | I3: CB | J3: =SUMIFS(Docentes!J:J,Docentes!F:F,"TD",Docentes!E:E,"CB") -> 0 | K3: =SUMIF(Docentes!F:F,"TD",Docentes!J:J) -> 0 | L3: CB | M3: =(1-((J3-G3)/J3))*100 -> #DIV/0! | N3: =(1-((K3-H3)/K3))*100 -> #DIV/0!
B4: CSC | C4: =COUNTIFS(Docentes!F:F,"TD",Docentes!E:E,"CSC",Docentes!J:J,">0") -> 0 | F4: CSC | G4: =COUNTIFS('Respuesta del Formulario'!X:X,"TD",'Respuesta del Formulario'!Y:Y,"CSC") -> 32 | I4: CSC | J4: =SUMIFS(Docentes!J:J,Docentes!F:F,"TD",Docentes!E:E,"CSC") -> 0 | L4: CSC | M4: =(1-((J4-G4)/J4))*100 -> #DIV/0!
B5: CSM | C5: =COUNTIFS(Docentes!F:F,"TD",Docentes!E:E,"CSM",Docentes!J:J,">0") -> 0 | F5: CSM | G5: =COUNTIFS('Respuesta del Formulario'!X:X,"TD",'Respuesta del Formulario'!Y:Y,"CSM") -> 23 | I5: CSM | J5: =SUMIFS(Docentes!J:J,Docentes!F:F,"TD",Docentes!E:E,"CSM") -> 0 | L5: CSM | M5: =(1-((J5-G5)/J5))*100 -> #DIV/0!
B6: Mixto | C6: =COUNTIFS(Docentes!F:F,"TD",Docentes!E:E,"CB,CSC",Docentes!J:J,">0") +COUNTIFS(Docentes!F:F,"TD",Docentes!E:E,"CB,CSM",Docentes!J:J,">0") +COUNTIFS(Docentes!F:F,"TD",Docentes!E:E,"CSC,CSM",Docentes!J:J,">0") -> 0 | I6: Mixto | J6: =SUMIFS(Docentes!J:J,Docentes!F:F,"TD",Docentes!E:E,"CB,CSC")+SUMIFS(Docentes!J:J,Docentes!F:F,"TD",Docentes!E:E,"CB,CSM")+SUMIFS(Docentes!J:J,Docentes!F:F,"TD",Docentes!E:E,"CSC,CSM")+SUMIFS(Docentes!J:J,Docentes!F:F,"TD",Docentes!E:E,"CB,CSC,CSM") -> 0
A7: Nocturno | B7: CB | C7: =COUNTIFS(Docentes!F:F,"TN",Docentes!E:E,"CB",Docentes!J:J,">0") -> 0 | D7: =COUNTIFS(Docentes!F:F,"TN",Docentes!J:J,">0") -> 0 | E7: =COUNTIFS(Docentes!F:F,"TN",Docentes!J:J,"=0") -> 0 | F7: CB | G7: =COUNTIFS('Respuesta del Formulario'!X:X,"TN",'Respuesta del Formulario'!Y:Y,"CB") -> 17 | H7: =COUNTIFS('Respuesta del Formulario'!X:X,"TN") -> 24 | I7: CB | J7: =SUMIFS(Docentes!J:J,Docentes!F:F,"TN",Docentes!E:E,"CB") -> 0 | K7: =SUMIF(Docentes!F:F,"TN",Docentes!J:J) -> 0 | L7: CB | M7: =(1-((J7-G7)/J7))*100 -> #DIV/0! | N7: =(1-((K7-H7)/K7))*100 -> #DIV/0!
B8: CSC | C8: =COUNTIFS(Docentes!F:F,"TN",Docentes!E:E,"CSC",Docentes!J:J,">0") -> 0 | F8: CSC | G8: =COUNTIFS('Respuesta del Formulario'!X:X,"TN",'Respuesta del Formulario'!Y:Y,"CSC") -> 4 | I8: CSC | J8: =SUMIFS(Docentes!J:J,Docentes!F:F,"TN",Docentes!E:E,"CSC") -> 0 | L8: CSC | M8: =(1-((J8-G8)/J8))*100 -> #DIV/0!
B9: CSM | C9: =COUNTIFS(Docentes!F:F,"TN",Docentes!E:E,"CSM",Docentes!J:J,">0") -> 0 | F9: CSM | G9: =COUNTIFS('Respuesta del Formulario'!X:X,"TN",'Respuesta del Formulario'!Y:Y,"CSM") -> 3 | I9: CSM | J9: =SUMIFS(Docentes!J:J,Docentes!F:F,"TN",Docentes!E:E,"CSM") -> 0 | L9: CSM | M9: =(1-((J9-G9)/J9))*100 -> #DIV/0!
B10: Mixto | C10: =COUNTIFS(Docentes!F:F,"TN",Docentes!E:E,"CB,CSC",Docentes!J:J,">0") +COUNTIFS(Docentes!F:F,"TD",Docentes!E:E,"CB,CSM",Docentes!J:J,">0") +COUNTIFS(Docentes!F:F,"TD",Docentes!E:E,"CSC,CSM",Docentes!J:J,">0") -> 0 | I10: Mixto | J10: =SUMIFS(Docentes!J:J,Docentes!F:F,"TN",Docentes!E:E,"CB,CSC")+SUMIFS(Docentes!J:J,Docentes!F:F,"TN",Docentes!E:E,"CB,CSM")+SUMIFS(Docentes!J:J,Docentes!F:F,"TN",Docentes!E:E,"CSC,CSM")+SUMIFS(Docentes!J:J,Docentes!F:F,"TN",Docentes!E:E,"CB,CSC,CSM") -> 0

Sheet Fichas_Alumnos
A1: Timestamp | B1: Apellido del Estudiante | C1: Nombre del Estudiante | D1: DNI | E1: Nacionalidad | F1: Fecha Nacimiento | G1: Email Address | H1: Email ALU | I1: Distrito | J1: Municipio | K1: Calle | L1: CP | M1: Tutor1Nombre | N1: Tutor1Apellido | O1: Tutor1Telefono | P1: Tutor1Email | Q1: Tutor2Nombre | R1: Tutor2Apellido | S1: Tutor2Telefono | T1: Tutor2Email | U1: Ficha Salud | V1: Año | W1: División | X1: Turno | Y1: Especialidad

Sheet Errores
A1: Timestamp | B1: Email Alumno | C1: Alumno | D1: Motivo

Sheet Historial docente
A1: Apellido y Nombre | B1: Email | C1: DNI | D1: Ciclos | E1: Turno | F1: Horas | G1: Horas sin Alumnos | H1: Maximo teórico | I1: Máx Alumnos | J1: Alumnos asignados | K1: Vacantes Disponibles | L1: Column 1
